Workbook

Sheet Notes
A1: 变压器快速设计/校核工具 v2 · Excel 版（由 v2 引擎公式生成）
A3: 用法：只改「输入」表黄色单元格；「计算」表全为公式；「校核」表给判定；「磁芯库/材质」表按数据手册维护。
A4: 权威实现是同目录的 transformer_design_tool_v2.html（含 LLC 谐振腔设计、磁芯逐项对比、输入电压扫描、供应商承认书校核模式）。本表用于在 Excel 里改参数与出报告。
A6: 核心公式（全部基于伏秒平衡，不使用正弦 4.44 系数）：
A7: 磁通 ΔB = V·t/(Np·Ae)，V·t = 施加电压 × 导通时间
A8: 变比：反激 Vo=Vin·D/((1-D)n)；正激 Vo=Vin·D/n；推挽/全桥 Vo=2Vin·D/n；半桥 Vo=Vin·D/n；LLC 谐振点 Vo=Vin_nom/(2n)
A9: 匝数 Np = max(磁通下限, 不饱和下限)；Ns 默认取四舍五入（可手动覆盖）；占空比是否超限在「校核」表提示
A10: 正激复位绕组 Nr/Np ≥ D/(1-D)（等价 D_max = Nr/(Nr+Np)，1:1 时 D≤0.5）
A11: 反激 Ipk = (Pin/(Vin_min·D_max))/(1-K/2)，Lp = Vin_min·D_max/(ΔI·Fs)；K≥2 时按 BCM 2·Pin/(Vin·D)
A12: 电流有效值用梯形精确式 √(D(Ia²+Ia·Ib+Ib²)/3)；反激副边 Is_pk = n·Ipk
A13: 气隙 AL = µ0·Ae/(lg+le/µi)；线圈 DCR = ρ·MLT·N/A_cu（本表按 100°C 折算）
A14: 损耗 P_cu=ΣI_rms²·R_dc·F_R；P_core = Pcv_ref·(Fs/100kHz)^α·(B_ac/100mT)^β·Ve，B_ac=ΔB_pp/2；ΔT=(P_core+P_cu)·Rth
... A25: 可信边界：公式与内部一致性由 379 项自动检查覆盖（含 2800 例随机工况），但无样机实测对照；磁芯/材质数据必须按数据手册覆盖；漏感、EMI、绝缘、瞬态未建模。

Sheet Inputs
A1: 设计输入（黄色=需填写/选择）
A3: 拓扑 / Topology | B3: Flyback | C3: 下拉选择，全部公式按此分支
A4: 磁芯型号 / Core model | B4: EE25/13/7 | C4: 取自"磁芯库"，可按数据手册修改
A5: 材质 / Material | B5: PC40 | C5: 取自"材质"表
A6: 副边整流方式 (ct/bridge) | B6: ct | C6: 桥式/推挽中心抽头按 2 个副边绕组统计窗口
A7: Vin_nom (V)（LLC 用，0=取中点） | B7: 0 | C7: LLC 额定输入
A8: Ns 手动覆盖（0=按公式取整） | B8: 0 | C8: 评审供应商方案时直接填其匝数
A9: Vin_min (V) | B9: 9
A10: Vin_max (V) | B10: 36
A11: Vout (V) | B11: 12
A12: Iout (A) | B12: 2
A13: Vf (V) | B13: 0.5 | C13: 输出整流压降
A14: Fs (kHz) | B14: 100
A15: eta | B15: 0.9
A16: D_max（Vin_min 处） | B16: 0.45 | C16: 反激=开关；正激=单管；桥式=每管
A17: ΔB_target (T) | B17: 0.2 | C17: 允许磁通摆幅（峰峰）
A18: Bsat 降额系数 | B18: 0.8
A19: 纹波比 K=ΔI/Ipk（反激类） | B19: 0.4 | C19: 2=BCM 边界
A20: 输出电感纹波 ΔI_L (A) | B20: 0.6 | C20: 正激/桥式，Vin_min 设计点
A21: 目标电流密度 J (A/mm²) | B21: 4
A22: 窗口利用率上限 Ku | B22: 0.4
A23: 绕线填充系数 k_pack | B23: 1.25 | C23: 排绕≈1.1、乱绕1.2~1.4
A24: 热阻 Rth (K/W) | B24: 28
A25: 目标温升 ΔT (K) | B25: 40
A26: 环境温度 Tamb (°C) | B26: 40
A27: 高频电阻系数 F_R | B27: 1.2
A28: 输出纹波允许值 (% of Vout) | B28: 1
A29: 输出电容 ESR (Ω) | B29: 0.01
A30: 同步整流 Rds(on) (mΩ) | B30: 10
A31: SR 体二极管压降 (V) | B31: 0.8
A32: 死区时间 t_dead (ns) | B32: 200
A33: 原边线径模式 (auto/mm) | B33: mm | C33: auto 只自动取线径；股数用输入值
A34: 原边单股线径 (mm) | B34: 0.4 | C34: 手动模式
A35: 原边股数 | B35: 10
A36: 原边并联绕组数 | B36: 1
A37: 副边线径模式 (auto/mm) | B37: mm
A38: 副边单股线径 (mm) | B38: 0.4
A39: 副边股数 | B39: 10
A40: 副边并联绕组数 | B40: 1

Sheet Cores
A1: 型号 model | B1: 族 family | C1: Ae (mm²) | D1: le (mm) | E1: Aw (mm²) | F1: MLT (mm) | G1: 实测 AL (nH/N²) | H1: 来源 src | I1: 备注 note
A2: EE16/8/5 | B2: EE | C2: 20.1 | D2: 37.6 | E2: 26 | F2: 34 | H2: preset | I2: 族量级典型值，请按数据手册覆盖
A3: EE19/8/5 | B3: EE | C3: 22.5 | D3: 39.4 | E3: 33 | F3: 36 | H3: preset | I3: 族量级典型值
A4: EE25/13/7 | B4: EE | C4: 52.2 | D4: 57.5 | E4: 54 | F4: 50 | H4: preset | I4: 族量级典型值
A5: EE30/15/7 | B5: EE | C5: 60 | D5: 67 | E5: 73 | F5: 57 | H5: preset | I5: 族量级典型值
A6: EE35/18/11 | B6: EE | C6: 101 | D6: 68.4 | E6: 106 | F6: 66 | H6: preset | I6: 族量级典型值
A7: EFD15/8/5 | B7: EFD | C7: 15 | D7: 34 | E7: 19 | F7: 33 | H7: preset | I7: 族量级典型值
A8: EFD20/10/7 | B8: EFD | C8: 31 | D8: 46.5 | E8: 39 | F8: 41 | H8: preset | I8: 族量级典型值
A9: EFD30/15/9 | B9: EFD | C9: 69 | D9: 64.8 | E9: 82 | F9: 52 | H9: preset | I9: 族量级典型值
A10: ETD29/16/10 | B10: ETD | C10: 76 | D10: 70.4 | E10: 104 | F10: 62 | H10: preset | I10: 族量级典型值
A11: ETD34/17/11 | B11: ETD | C11: 97.1 | D11: 78.6 | E11: 138 | F11: 68 | H11: preset | I11: 族量级典型值
A12: PQ26/20 | B12: PQ | C12: 118 | D12: 46.9 | E12: 76 | F12: 50 | H12: preset | I12: 族量级典型值
A13: PQ35/35 | B13: PQ | C13: 212 | D13: 60.4 | E13: 158 | F13: 62 | H13: preset | I13: 族量级典型值
... A20: EPC13 | B20: EPC | C20: 12.1 | D20: 24.2 | E20: 14 | F20: 29 | H20: preset | I20: 族量级典型值
A21: EPC19 | B21: EPC | C21: 52 | D21: 32 | E21: 38 | F21: 38 | G21: 1146 | H21: measured | I21: AL=1146nH/N²、MLT≈38mm 来自天胜 TST1724 承认书；Ae=52/le=32/Aw=38 由 19V/75W 输出电感不饱和反推（待手册确认，两个供应商数据均已印证）
A22: EPC25 | B22: EPC | C22: 30 | D22: 35 | E22: 34 | F22: 42 | H22: preset | I22: 族量级典型值
A23: Custom | B23: CUSTOM | C23: 50 | D23: 55 | E23: 50 | F23: 50 | H23: user | I23: 自定义：自行填写几何与实测 AL

Sheet Materials
A1: 材质 | B1: µi | C1: Bsat@100°C (T) | D1: Pcv_ref@100kHz/100mT (kW/m³) | E1: α | F1: β | G1: 备注
A2: PC40 | B2: 2300 | C2: 0.39 | D2: 70 | E2: 1.45 | F2: 2.5 | G2: 典型值，请按数据手册校核
A3: PC44 | B3: 2400 | C3: 0.39 | D3: 60 | E3: 1.45 | F3: 2.5 | G3: 典型值，请按数据手册校核
A4: PC95 | B4: 3300 | C4: 0.4 | D4: 50 | E4: 1.5 | F4: 2.45 | G4: 典型值，请按数据手册校核
A5: N27 | B5: 2000 | C5: 0.38 | D5: 110 | E5: 1.45 | F5: 2.45 | G5: 典型值，请按数据手册校核
A6: N87 | B6: 2200 | C6: 0.39 | D6: 70 | E6: 1.45 | F6: 2.45 | G6: 典型值，请按数据手册校核
A7: N97 | B7: 2300 | C7: 0.41 | D7: 45 | E7: 1.5 | F7: 2.4 | G7: 典型值，请按数据手册校核
A8: 3C90 | B8: 2300 | C8: 0.32 | D8: 80 | E8: 1.45 | F8: 2.4 | G8: 典型值，请按数据手册校核
A9: 3C94 | B9: 2300 | C9: 0.33 | D9: 65 | E9: 1.45 | F9: 2.4 | G9: 典型值，请按数据手册校核
A10: 3F3 | B10: 1800 | C10: 0.29 | D10: 40 | E10: 1.6 | F10: 2.25 | G10: 典型值，请按数据手册校核
A11: 3F4 | B11: 1600 | C11: 0.3 | D11: 30 | E11: 1.65 | F11: 2.2 | G11: 典型值，请按数据手册校核

Sheet Calc
A1: 计算结果 / Calculations
A3: 拓扑 / Topology | B3: ='Inputs'!$B$3 | C3: 下拉选择，全部公式按此分支 | D3: B3
A4: 磁芯型号 / Core model | B4: ='Inputs'!$B$4 | C4: 取自"磁芯库"，可按数据手册修改 | D4: B4
A5: 材质 / Material | B5: ='Inputs'!$B$5 | C5: 取自"材质"表 | D5: B5
A6: 副边整流方式 (ct/bridge) | B6: ='Inputs'!$B$6 | C6: 桥式/推挽中心抽头按 2 个副边绕组统计窗口 | D6: B6
A7: Vin_nom (V)（LLC 用，0=取中点） | B7: ='Inputs'!$B$7 | C7: LLC 额定输入 | D7: B7
A8: Ns 手动覆盖（0=按公式取整） | B8: ='Inputs'!$B$8 | C8: 评审供应商方案时直接填其匝数 | D8: B8
A9: Vin_min (V) | B9: ='Inputs'!$B$9 | D9: B9
A10: Vin_max (V) | B10: ='Inputs'!$B$10 | D10: B10
A11: Vout (V) | B11: ='Inputs'!$B$11 | D11: B11
A12: Iout (A) | B12: ='Inputs'!$B$12 | D12: B12
A13: Vf (V) | B13: ='Inputs'!$B$13 | C13: 输出整流压降 | D13: B13
A14: Fs (kHz) | B14: ='Inputs'!$B$14 | D14: B14
A15: eta | B15: ='Inputs'!$B$15 | D15: B15
A16: D_max（Vin_min 处） | B16: ='Inputs'!$B$16 | C16: 反激=开关；正激=单管；桥式=每管 | D16: B16
A17: ΔB_target (T) | B17: ='Inputs'!$B$17 | C17: 允许磁通摆幅（峰峰） | D17: B17
A18: Bsat 降额系数 | B18: ='Inputs'!$B$18 | D18: B18
A19: 纹波比 K=ΔI/Ipk（反激类） | B19: ='Inputs'!$B$19 | C19: 2=BCM 边界 | D19: B19
A20: 输出电感纹波 ΔI_L (A) | B20: ='Inputs'!$B$20 | C20: 正激/桥式，Vin_min 设计点 | D20: B20
A21: 目标电流密度 J (A/mm²) | B21: ='Inputs'!$B$21 | D21: B21
A22: 窗口利用率上限 Ku | B22: ='Inputs'!$B$22 | D22: B22
A23: 绕线填充系数 k_pack | B23: ='Inputs'!$B$23 | C23: 排绕≈1.1、乱绕1.2~1.4 | D23: B23
A24: 热阻 Rth (K/W) | B24: ='Inputs'!$B$24 | D24: B24
A25: 目标温升 ΔT (K) | B25: ='Inputs'!$B$25 | D25: B25
A26: 环境温度 Tamb (°C) | B26: ='Inputs'!$B$26 | D26: B26
A27: 高频电阻系数 F_R | B27: ='Inputs'!$B$27 | D27: B27
A28: 输出纹波允许值 (% of Vout) | B28: ='Inputs'!$B$28 | D28: B28
A29: 输出电容 ESR (Ω) | B29: ='Inputs'!$B$29 | D29: B29
A30: 同步整流 Rds(on) (mΩ) | B30: ='Inputs'!$B$30 | D30: B30
A31: SR 体二极管压降 (V) | B31: ='Inputs'!$B$31 | D31: B31
A32: 死区时间 t_dead (ns) | B32: ='Inputs'!$B$32 | D32: B32
A33: 原边线径模式 (auto/mm) | B33: ='Inputs'!$B$33 | C33: auto 只自动取线径；股数用输入值 | D33: B33
A34: 原边单股线径 (mm) | B34: ='Inputs'!$B$34 | C34: 手动模式 | D34: B34
A35: 原边股数 | B35: ='Inputs'!$B$35 | D35: B35
A36: 原边并联绕组数 | B36: ='Inputs'!$B$36 | D36: B36
A37: 副边线径模式 (auto/mm) | B37: ='Inputs'!$B$37 | D37: B37
A38: 副边单股线径 (mm) | B38: ='Inputs'!$B$38 | D38: B38
A39: 副边股数 | B39: ='Inputs'!$B$39 | D39: B39
A40: 副边并联绕组数 | B40: ='Inputs'!$B$40 | D40: B40
A41: Fs (Hz) | B41: =$B$14*1000 | D41: B41
...

Sheet Checks
A1: 校核 / Checks（判定公式，随输入自动更新）
A3: 磁通峰值 Bpk ≤ Bsat·降额 | B3: =Calc!$B$97 | C3: =Calc!$B$93 | D3: =IF(B3<=C3,"通过","不通过")
A4: Vin_min 所需占空比 D ≤ 上限 | B4: =Calc!$B$88 | C4: =Calc!$B$62 | D4: =IF(B4<=C4,"通过","不通过（需增大 Np 或提高 D 上限）")
A5: 窗口填充率 ≤ Ku | B5: =Calc!$B$119 | C5: =Calc!$B$22*100 | D5: =IF(B5<=C5,"通过","不通过（换大磁芯或减线径）")
A6: 原边电流密度（参考，以温升为准） | B6: =Calc!$B$121 | C6: =Calc!$B$21*1.25 | D6: =IF(B6<=C6,"通过","高于目标 J，若温升允许可接受")
A7: 副边电流密度（参考，以温升为准） | B7: =Calc!$B$122 | C7: =Calc!$B$21*1.25 | D7: =IF(B7<=C7,"通过","高于目标 J，若温升允许可接受")
A8: 温升 ΔT ≤ 目标 | B8: =Calc!$B$139 | C8: =Calc!$B$25 | D8: =IF(B8<=C8,"通过","不通过（需降损耗或改散热）")
A9: 正激复位绕组 Nr/Np ≥ D/(1-D) | B9: =IF(Calc!$B$53=TRUE,Calc!$B$117/Calc!$B$84,1) | C9: =IF(Calc!$B$53=TRUE,Calc!$B$63/(1-Calc!$B$63),1) | D9: =IF(B9>=C9,"通过","不通过：复位时间不足")
A10: 输出电感 Bpk ≤ 允许值 | B10: =Calc!$B$147 | C10: =IF(Calc!$B$59,Calc!$B$93,999) | D10: =IF(B10<=C10,"通过/不适用","不通过（电感磁芯偏小）")
A11: 输出电感气隙（≤2mm 工程可用） | B11: =Calc!$B$146 | C11: =IF(Calc!$B$59,2,999) | D11: =IF(B11<=C11,"通过/不适用","气隙过大：改磁芯或磁粉芯")
A12: 输出电容 ESR 占纹波预算 ≤50% | B12: =Calc!$B$151/Calc!$B$148*100 | C12: =50 | D12: =IF(B12<=C12,"通过","ESR 主导：需更低 ESR 或多只并联（C 列为 0 表示 ESR 单独已超预算）")
A14: 活体自检 / Self-consistency（相对偏差，应≈0）
A15: ΔB 两条路径：V·t/(Np·Ae) vs Lp·ΔI/(Np·Ae)（反激） | B15: =ABS(Calc!$B$90/(Calc!$B$84*Calc!$B$74)-(Calc!$B$77/1000000)*Calc!$B$78/(Calc!$B$84*Calc!$B$74))/MAX(Calc!$B$90/(Calc!$B$84*Calc!$B$74),0.000001)
A16: Lm = AL·Np² 往返 | B16: =ABS(Calc!$B$94/1000000000*Calc!$B$84*Calc!$B$84-(Calc!$B$95/1000000))/(Calc!$B$95/1000000)
A17: 填充率往返：铜面积×k_pack/Aw | B17: =ABS(Calc!$B$119/100*Calc!$B$44/Calc!$B$23-Calc!$B$118)/MAX(Calc!$B$118,0.000001)
A18: 实测 AL 与几何推算 µ0·µi·Ae/le 的偏差（信息项：几何可疑时会明显偏离） | B18: =IF(Calc!$B$46=0,0,ABS(Calc!$B$46-1000000*4*PI()*0.0000001*Calc!$B$47*Calc!$B$74/(Calc!$B$43/1000))/(1000000*4*PI()*0.0000001*Calc!$B$47*Calc!$B$74/(Calc!$B$43/1000)))
